Workbook

Sheet Raw_data
A1: start | B1: end | C1: start-geopoint | D1: _start-geopoint_latitude | E1: _start-geopoint_longitude | F1: _start-geopoint_altitude | G1: _start-geopoint_precision | H1: today | I1: अवलोकनकर्ता का नाम | J1: यदि अन्य तो कृपया नाम दर्ज करें - | K1: कक्षा अवलोकन दिनांक | L1: क्या आप चयनित मास्टर ट्रैनर का अवलोकन कर रहे है? | M1: जिला | N1: ब्लॉक | O1: कृपया शाला का UDISE कोड दर्ज करें | P1: मास्टर ट्रैनर का नाम | Q1: विषय | R1: क्या अवलोकन के दौरान पढ़ाया जा रहा पाठ उसी विषय पर था जो ऊपर चुना गया था? | S1: कृपया अवलोकन का विषय दर्ज करें - | T1: यदि अन्य, तो कृपया दर्ज करें | U1: शिक्षक/शिक्षिका का लिंग | V1: शिक्षिका/शिक्षक का नाम? | W1: शिक्षिका/शिक्षक का यूनीक आइडी? | X1: क्या ये शिक्षक/शिक्षिका, 2 दिवसीय विषय-आधारित प्रशिक्षण में मास्टर ट्रेनर (MT) रहे हैं? | Y1: आपने कौनसी कक्षा का अवलोकन किया? | Z1: आपने कौनसी कक्षा का अवलोकन किया?/कक्षा 6 | AA1: आपने कौनसी कक्षा का अवलोकन किया?/कक्षा 7 | AB1: आपने कौनसी कक्षा का अवलोकन किया?/कक्षा 8 | AC1: आपका कुल शिक्षण अनुभव कितने महीनों का है? (शासकीय एवं गैर-शासकीय) | AD1: शिक्षक कक्षा 6-8 में कितने महीनों से पढ़ा रहें हैं? | AE1: चयनित विषय को शिक्षक कितने महीनों पढ़ा रहें हैं? | AF1: आपने किस प्रकार की कक्षा का अवलोकन किया? | AG1: शिक्षक ने किस विषय के साथ अपना बी. एड. या डी. एड. पूरा किया है? | AH1: शिक्षक ने किस विषय के साथ अपना बी. एड. या डी. एड. पूरा किया है?/हिन्दी | AI1: शिक्षक ने किस विषय के साथ अपना बी. एड. या डी. एड. पूरा किया है?/इंग्लिश | AJ1: शिक्षक ने किस विषय के साथ अपना बी. एड. या डी. एड. पूरा किया है?/उर्दू | AK1: शिक्षक ने किस विषय के साथ अपना बी. एड. या डी. एड. पूरा किया है?/मराठी | AL1: शिक्षक ने किस विषय के साथ अपना बी. एड. या डी. एड. पूरा किया है?/संस्कृत | AM1: शिक्षक ने किस विषय के साथ अपना बी. एड. या डी. एड. पूरा किया है?/गणित | AN1: शिक्षक ने किस विषय के साथ अपना बी. एड. या डी. एड. पूरा किया है?/विज्ञान | AO1: शिक्षक ने किस विषय के साथ अपना बी. एड. या डी. एड. पूरा किया है?/सामाजिक विज्ञान | AP1: शिक्षक ने किस विषय के साथ अपना बी. एड. या डी. एड. पूरा किया है?/अन्य | AQ1: यदि अन्य तो दर्ज करें | AR1: किस विषय को पढ़ाने मे आप सबसे ज्यादा सहज महसूस करते है? | AS1: कक्षा मे कुल नामांकित विद्यार्थी की संख्या | AT1: कक्षा मे कुल उपस्थित विद्यार्थी की संख्या | AU1: 1. शिक्षक कालांश की शुरुआत कैसे करते हैं? (जैसे-पाठ या विषय-वस्तु के बारें मे बताना, कक्षा के अधिकांश विद्यार्थियों से हालचाल पूछना एवं स्वागत करना, कोई हुक उपयोग करना, विद्यार्थियों के जीवन से जुड़ी बातचीत करके उनका विषयवस्तु से जुड़ाव बनाना) | AV1: 2.1. शिक्षक कक्षा में कैसे पढ़ाते हैं? (एक से अधिक विकल्प चुने जा सकते हैं) | AW1: 2.1. शिक्षक कक्षा में कैसे पढ़ाते हैं? (एक से अधिक विकल्प चुने जा सकते हैं)/i. व्याख्यान करते हैं। | AX1: 2.1. शिक्षक कक्षा में कैसे पढ़ाते हैं? (एक से अधिक विकल्प चुने जा सकते हैं)/ii. विद्यार्थियों से पाठ के कुछ हिस्सों को पढ़ने के लिए कहते हैं। | AY1: 2.1. शिक्षक कक्षा में कैसे पढ़ाते हैं? (एक से अधिक विकल्प चुने जा सकते हैं)/iii. टीएलएम का उपयोग करते हैं (पाठ्यपुस्तक और ब्लैक/वाइट बोर्ड के अलावा) | AZ1: 2.1. शिक्षक कक्षा में कैसे पढ़ाते हैं? (एक से अधिक विकल्प चुने जा सकते हैं)/iv. गतिविधि या खेल | BA1: 2.1. शिक्षक कक्षा में कैसे पढ़ाते हैं? (एक से अधिक विकल्प चुने जा सकते हैं)/v. अन्य | BB1: यदि अन्य | BC1: 2.2. पाठ के दौरान विद्यार्थियों की सहभागिता (विद्यार्थियों द्वारा प्रश्न पूछना, तर्क देना या दोहराना एवं पाठ के दौरान अपने विचार साझा करना साथ ही प्रश्नो पर उत्तर देना शामिल हैं) कितनी है? | BD1: 2.3. विद्यार्थियों की सहभागिता के लिए कौन कौन सी तकनीकें उपयोग की गई हैं? (एक से अधिक विकल्प चुनें जा सकते हैं) | BE1: 2.3. विद्यार्थियों की सहभागिता के लिए कौन कौन सी तकनीकें उपयोग की गई हैं? (एक से अधिक विकल्प चुनें जा सकते हैं)/i.हुक का प्रयोग | BF1: 2.3. विद्यार्थियों की सहभागिता के लिए कौन कौन सी तकनीकें उपयोग की गई हैं? (एक से अधिक विकल्प चुनें जा सकते हैं)/ii.थिंक पेयर शेयर | BG1: 2.3. विद्यार्थियों की सहभागिता के लिए कौन कौन सी तकनीकें उपयोग की गई हैं? (एक से अधिक विकल्प चुनें जा सकते हैं)/iii.समूह चर्चा | BH1: 2.3. विद्यार्थियों की सहभागिता के लिए कौन कौन सी तकनीकें उपयोग की गई हैं? (एक से अधिक विकल्प चुनें जा सकते हैं)/iv.ऑडियो/ विडियो का उपयोग करके शिक्षण | BI1: 2.3. विद्यार्थियों की सहभागिता के लिए कौन कौन सी तकनीकें उपयोग की गई हैं? (एक से अधिक विकल्प चुनें जा सकते हैं)/v.विद्यार्थी के कार्यों (अकादमिक/गैर अकादमिक) पर रचनात्मक फीडबैक (Constructive Feedback) | BJ1: 2.3. विद्यार्थियों की सहभागिता के लिए कौन कौन सी तकनीकें उपयोग की गई हैं? (एक से अधिक विकल्प चुनें जा सकते हैं)/vi.इनमें से कोई नहीं देखा गया | BK1: 3.1. कक्षा में शिक्षक के द्वारा किस तरह के प्रश्न पूछे गए? | BL1: 3.2. क्या शिक्षक प्रश्न का उत्तर लेने से पहले विद्यार्थियों को स्पष्ट रूप से कह कर सोचने के लिए पर्याप्त समय देते हैं? | BM1: 3.3. शिक्षक उत्तर लेने के लिए विद्यार्थियों का चयन किस प्रकार करते हैं? (अधिकांशत : >50% प्रश्नो की संख्या के आधार पर) | BN1: 4. शिक्षक पढ़ाए जा रहे विषय/टॉपिक के बारे में विद्यार्थियों की समझ की जांच (CFU) करने के लिए किस तरीके का अधिकांशतः उपयोग करते हैं? (प्रश्नों की संख्या के आधार पर जांचा जाएगा) | BO1: 5.1. शिक्षक विद्यार्थियों को स्वतंत्र कार्य करने का समय प्रदान करते हैं एवं कक्षा में भ्रमण करके सहायता करते हैं। | BP1: 5.2. शिक्षक विद्यार्थियों को जोड़े या समूह कार्य के अवसर प्रदान करते हैं एवं कक्षा में भ्रमण करके सहायता करते हैं। | BQ1: 6.1. क्या शिक्षक किसी भी विद्यार्थी के साथ अपमानजनक भाषा* या व्यवहार करते हैं, या विद्यार्थियों को शारीरिक दंड देते हैं ? (*जैसे चिल्लाना/डांटना/उपहास/शर्मिंदा करना या सांस्कृतिक/क्षेत्रीय रूप से अपमान सूचक शब्दों का इस्तेमाल आदि) | BR1: यदि हाँ, तो कृपया उदाहरण का विवरण दे - | BS1: 6.2. शिक्षक विद्यार्थियों के साथ सकारात्मक और प्रेरणादायी भाषा का उपयोग करते हैं (मोटिवेशनल या प्रशंसा करते हैं)| | BT1: 7. क्या शिक्षक कक्षा के लिए प्रभावी नियम या दिनचर्या /रूटीन बनाए रखने में सक्षम थे? | BU1: 8.1. क्या शिक्षक रूढ़िवादिता या भेदभाव जैसे किसी भी मुद्दे पर सजगता से बातचीत कर समावेशी वातावरण को बढ़ावा देते हैं? (अगर शिक्षक द्वारा एक भी नकारात्मक घटना दिखे तो विकल्प ii को चुना जाए) | BV1: 8.2. क्या शिक्षक रूढ़िवादिता या भेदभाव की किसी भी घटना/मुद्दे को संबोधित कर समावेशी वातावरण को बढ़ावा देते है? | BW1: 9.1. क्या शिक्षक के पास आज की कक्षा के लिए लिखित पाठ योजना है (स्वयं निर्मित या राज्य से पूर्व-तैयार)? | BX1: 9.2. क्या पाठ योजना में निम्नलिखित का उल्लेख है: (एक से अधिक विकल्प चुनें जा सकते हैं) | BY1: 9.2. क्या पाठ योजना में निम्नलिखित का उल्लेख है: (एक से अधिक विकल्प चुनें जा सकते हैं)/i.सीखने के प्रतिफल/लर्निंग आउट्कम | BZ1: 9.2. क्या पाठ योजना में निम्नलिखित का उल्लेख है: (एक से अधिक विकल्प चुनें जा सकते हैं)/ii.आवश्यक सामग्री (जैसे: टीएलएम) | CA1: 9.2. क्या पाठ योजना में निम्नलिखित का उल्लेख है: (एक से अधिक विकल्प चुनें जा सकते हैं)/iii.गतिविधियों का विवरण (जैसे: प्रयोग, खेल, चर्चा, समूह कार्य आदि) | CB1: 9.2. क्या पाठ योजना में निम्नलिखित का उल्लेख है: (एक से अधिक विकल्प चुनें जा सकते हैं)/iv.समझ की जांच (CFU) हेतु प्रश्न | CC1: 9.2. क्या पाठ योजना में निम्नलिखित का उल्लेख है: (एक से अधिक विकल्प चुनें जा सकते हैं)/v.गृहकार्य | CD1: 9.2. क्या पाठ योजना में निम्नलिखित का उल्लेख है: (एक से अधिक विकल्प चुनें जा सकते हैं)/vi.उपरोक्त में से कोई भी नहीं | CE1: 9.3. पढ़ाया गया पाठ, पाठ योजना के कितना अनुरूप था? | CF1: 10. क्या शिक्षक ने पाठ पढ़ाने के दौरान निम्नलिखित घटकों को शामिल किया? (एक से अधिक विकल्प चुनें जा सकते हैं) | CG1: 10. क्या शिक्षक ने पाठ पढ़ाने के दौरान निम्नलिखित घटकों को शामिल किया? (एक से अधिक विकल्प चुनें जा सकते हैं)/i.TLM का उपयोग किया | CH1: 10. क्या शिक्षक ने पाठ पढ़ाने के दौरान निम्नलिखित घटकों को शामिल किया? (एक से अधिक विकल्प चुनें जा सकते हैं)/ii.विषय से संबंधित गतिविधियाँ | CI1: 10. क्या शिक्षक ने पाठ पढ़ाने के दौरान निम्नलिखित घटकों को शामिल किया? (एक से अधिक विकल्प चुनें जा सकते हैं)/iii.समझ की जाँच (CFU) प्रश्न | CJ1: 10. क्या शिक्षक ने पाठ पढ़ाने के दौरान निम्नलिखित घटकों को शामिल किया? (एक से अधिक विकल्प चुनें जा सकते हैं)/iv.गृहकार्य देना | CK1: 10. क्या शिक्षक ने पाठ पढ़ाने के दौरान निम्नलिखित घटकों को शामिल किया? (एक से अधिक विकल्प चुनें जा सकते हैं)/v.उपरोक्त में से कोई भी नहीं | CL1: A. क्या विद्यार्थियों की नोटबुक नियमित रूप से और तुरंत या उचित समय-सीमा के भीतर जांची जाती है? (4-5 रैंडम नोटबुक देखी जाएं) | CM1: B. क्या शिक्षक द्वारा, विद्यार्थियों की नोटबुक में त्रुटियां पहचानी और ठीक की जाती हैं? | CN1: C. क्या शिक्षक विद्यार्थियों के काम पर विशिष्ट और रचनात्मक फीडबैक प्रदान करते हैं? | CO1: D.1. क्या शिक्षक नोटबुक में उचित व व्यवस्थित लिखावट के साथ प्रस्तुतिकरण को प्रोत्साहित करते हैं? | CP1: D.2. विषय-विशिष्ट नोटबुक में कार्य कर रहे विद्यार्थियों की स्थिति | CQ1: E. कितने विद्यार्थियों के पास विषय की पाठ्य पुस्तकें थीं? | CR1: F.1. क्या कक्षा की दीवारों पर संदर्भ पोस्टर और चार्ट मौजूद हैं? | CS1: F.2. क्या अधिकांश चार्ट और पोस्टर नए या पुराने हैं? | CT1: F.3. क्या चार्ट विद्यार्थियों ने बनाए हैं, शिक्षकों ने बनाए हैं, या स्टोर से खरीदे गए हैं? | CU1: F.4. प्रासंगिकता - सीखने से संबंध | CV1: G.1. पढ़ने के कौशल की जांच: क्या विद्यार्थी धारा प्रवाह के साथ पढ़ पा रहें हैं? (अवलोकनकर्ता किन्ही 3 विद्यार्थियों को हिन्दी की किताब से किसी एक पैराग्राफ- 4-6 लाइन, को पढ़ने को कहेंगे।) | CW1: G.2. क्या विद्यार्थी पढ़कर समझ पा रहें हैं? (विद्यार्थी अपने शब्दों में सार बता पा रहें हैं, कम से कम 70% अंश सही है) | CX1: G.3. क्या विद्यार्थी लेखन कार्य कर पा रहें हैं? (उन्ही तीन विद्यार्थियों को कम से कम दो लाइन श्रुतलेख करवाया जा सकता है या पढे हुए को अपने शब्दों में लिख सकते हैं।) | CY1: Option 1 : कक्षा की शुरुआत में विद्यार्थियों के साथ विषय से जुड़ी सामान्य बातचीत करना, स्वागत करना एवं सभी विद्यार्थियों के साथ जुड़ाव बनाना, उनको सीखने के लिए तैयार करने के लिए जरूरी हैं। | CZ1: Option 2 : आपने कुछ विद्यार्थियों से हाल-चाल पूछने का अच्छा प्रयास किया हैं; कक्षा के सभी विद्यार्थियों के साथ शुरुआती बातचीत करना, कक्षा में उनका स्वागत करना, विषय से जुड़ी बातचीत करके भूमिका बनाना उन्हें सीखने की प्रक्रिया में जोड़ने के लिए बहुत आवश्यक है, आप अपनी कक्षा में इसे लागू करने पर जरूर विचार करें। | DA1: Option 3 : कक्षा की शुरुआत रोचक तरीके से करने का आपका प्रयास अच्छा है, इस से कक्षा में विद्यार्थियों की सक्रियता सुनिश्चित होती है; यह भी सुनिश्चित करें कि सभी विद्यार्थी कक्षा से जुड़ाव महसूस करें और यह समझें कि कक्षा में उनका स्वागत है। | DB1: iv.Option 4: कक्षा के प्रारंभ मे विद्यार्थियों के साथ बातचीत करना, उनका स्वागत करना एवं विषय वस्तु के साथ जुड़ाव बनाकर कक्षा की शुरुआत करने का आपका प्रयास प्रसंशनीय हैं, इस प्रयास को नियमित रखें एवं इसमें नवाचार के बारे में भी सोचें। | DC1: पाठ को और अधिक रुचिकर एवं प्रभावी बनाने के लिए विभिन्न तरीके जैसे व्याख्यान पद्धति, टीएलएम और विद्यार्थी गतिविधियों का उपयोग करने पर विचार करें और विद्यार्थियों की सहभागिता बढाएं। | DD1: अलग-अलग शिक्षण आवश्यकताओं को पूरा करने के लिए विविध शिक्षण विधियों/तरीकों का उत्कृष्ट उपयोग किया जा रहा है; समग्र सीख और सहभागिता आधारित शिक्षण को इसी तरह जारी रखें। | DE1: Option 1: विद्यार्थियों को प्रश्न पूछने, विचार साझा करने और चर्चाओं में भाग लेने के अवसर प्रदान करके उनकी अधिकतम भागीदारी को प्रोत्साहित करें। | DF1: Option 2: आपने पढ़ाते समय कुछ विद्यार्थियों को शामिल करने का अच्छा प्रयास किया; शिक्षण में अधिकतम विद्यार्थियों को शामिल करने के लिए आपको सहभागिता बढ़ाने के तरीकों को अपनाना चाहिए। (जैसे कोल्ड कालिंग, TPS, चर्चा आदि) | DG1: Option 3: कक्षा में विद्यार्थियों की सक्रिय भागीदारी और सहभागिता को बढ़ावा देने में आप बहुत बढ़िया काम कर रहे हैं; इसी तरह सीखने के परस्पर संवादात्मक (इंटरैक्टिव) वातावरण को बढ़ावा देते रहें। | DH1: Hook - हुक एक छोटी सी गतिविधि होती है ( जैसे कविता/कहानी/तथ्य/किस्सा/पहेली आदि) जिसे शिक्षक पढ़ाए जाने वाले पाठ के शुरू में, उस विषय में रुचि उत्पन्न करने के लिए उपयोग कर सकते हैं। हुक सीमित अवधि का होता है (3 मिनट से कम) विषय से संबंधित होता है और रुचिकर होना चाहिए। | DI1: TPS (थिंक-पेयर-शेयर)- जब शिक्षक कोई प्रश्न पूछते हैं, तो TPS तकनीक का उपयोग विद्यार्थियों को उस प्रश्न पर जवाब देने से पहले सहपाठी के साथ जोड़ी बनाकर सोचने, विचार करने और चर्चा करने का अवसर देने के लिए किया जाता है। | DJ1: समूह में चर्चा - यह विद्यार्थियों को अपने विचार व्यक्त करने और अन्य विचारों को सुनने का अवसर प्रदान करती है। | DK1: ऑडियो-वीडियो: इनके उपयोग से शिक्षण के तरीके में परिवर्तन विद्यार्थियों का ध्यान आकर्षित करने में मदद कर सकता है और उन्हें कक्षा मे रुचि एवं सक्रियता के साथ जोड़े रख सकता है। कुछ अवधारणाएँ (विशेष रूप से अमूर्त/जटिल) ऑडियो-वीडियो विधि के माध्यम से सरल और प्रभावी तरीके से समझायी जा सकती हैं। | DL1: Option 1 : विद्यार्थियों में पाठ के विषय के बारे में सोचने और अपने विचार बनाने को प्रोत्साहित करने और उनकी समझ/सीख का आकलन करने के लिए पाठ के दौरान प्रश्नों का उपयोग करें, यह शिक्षण प्रक्रिया का एक अभिन्न अंग है। | DM1: Option2 :आपने बंद-छोर वाले प्रश्नों का उपयोग करने का अच्छा प्रयास किया; इसको आगे बढ़ाते हुए आलोचनात्मक सोच और कक्षा में अधिक जुड़ाव को प्रोत्साहित करने के लिए खुले-छोर वाले प्रश्नों को शामिल करने का प्रयास करें। | DN1: Option3 :आपने प्रश्न के अलग-अलग प्रकारों का संतुलित उपयोग करने का उत्कृष्ट प्रयास किया; कक्षा में पढ़ाते समय इसी तरह विद्यार्थियों द्वारा विचारों की अभिव्यक्ति एवं सक्रिय भागीदारी को बढ़ाते रहें। | DO1: Option 1 : विद्यार्थियों के आत्मविश्वास और समझ/सीख को बढ़ाने के लिए उनसे प्रतिक्रिया लेने से पहले प्रश्न को समझने और जवाब सोचने के लिए स्पष्ट रूप से कह कर पर्याप्त समय देने पर विचार करें। | DP1: Option 2 : आपका विद्यार्थियों की प्रतिक्रिया लेने से पहले थोड़ा रुकने का प्रयास अच्छा है; विद्यार्थियों को सोचने का और समय प्रदान करने से और गहराई से सोचने एवं विचार करके उत्तर देने के लिए प्रोत्साहित किया जा सकता है। | DQ1: Option 3 : आपका विद्यार्थियों को सोचने और जवाब देने के लिए पर्याप्त समय देने का प्रयास बहुत उत्कृष्ट है; इसी तरह विद्यार्थियों को गहराई से चिंतन करने के वातावरण को बढ़ावा देते रहें। | DR1: Option 1 : सभी विद्यार्थियों की सक्रिय भागीदारी सुनिश्चित करने और उन्हें व्यक्तिगत रूप से समझने के लिए प्रत्येक विद्यार्थी को प्रतिक्रिया देने के अवसर प्रदान करें साथ ही छात्रों को इसके लिए प्रोत्साहित करें। | DS1: Option 2 : आपका स्वेच्छा से उत्तर देने वाले विद्यार्थियों पर ध्यान देना या उन्हें संबोधित करना/उत्तर प्राप्त करना एक अच्छा तरीका है; हालांकि कक्षा में विद्यार्थियों के बड़े समूह को शिक्षण प्रक्रिया में शामिल करने के लिए विद्यार्थियों का चयन अनियमित या रेन्डम आधार पर करें इसके लिए कोल्ड कालिंग का उपयोग कर सकते हैं। | DT1: Option 3 : आपका समान एवं निष्पक्ष भागीदारी सुनिश्चित करने के लिए विद्यार्थियों के चयन की अनियमित या रेन्डम तकनीक का उपयोग करना उत्कृष्ट प्रयास हैं; सभी विद्यार्थियों की समझ के स्तर को जानने के साथ-साथ उनके जुड़ाव को बढ़ावा देने के लिए इन तरीकों का अच्छी तरह से उपयोग करना जारी रखें। | DU1: If Option 1 or 2 are selected : समझ की जांच के लिए कुछ बुनियादी तकनीकों का अच्छा उपयोग किया। साथ ही विद्यार्थियों की समझ की और गहराई से जांच करने के लिए अधिक विस्तृत/व्यापक आकलन के तरीकों को शामिल करने पर विचार करें (जैसे एग्जिट टिकट, व्यक्तिगत प्रश्न पूछना आदि) | DV1: Option 3 : आपका आकलन के माध्यम से सक्रिय रूप से समझ की जाँच करने का तरीका उत्कृष्ट हैं; समग्र शिक्षण सुनिश्चित करने के लिए इसी तरह जांच के तरीकों का उपयोग करते रहें। | DW1: Option 4 : पाठ के दौरान विद्यार्थियों की समझ को नियमित रूप से जाँचना शिक्षण प्रक्रिया को और बेहतर बनाता है, विद्यार्थियों की समझ की और गहराई से जांच करने के लिए विस्तृत/व्यापक आकलन के तरीकों को शामिल करने पर विचार करें (जैसे एग्जिट टिकट, व्यक्तिगत प्रश्न पूछना आदि) | DX1: Option 1 :विद्यार्थियों को स्वयं अवधारणाओं का अभ्यास करने और उनकी समझ और प्रगति के स्तर को जानने के लिए स्वतंत्र कार्य समय (Independent work time) को शामिल करें। | DY1: Option 2 : बहुत अच्छा है कि विद्यार्थियों को स्वतंत्र कार्य (Independent work) का समय दिया जाता है;इसके साथ ही कक्षा में भ्रमण करते हुए विद्यार्थियों को सहयोग करते रहें ताकि ये सुनिश्चित किया जा सके कि वे सही दिशा मे कार्य कर रहे हैं, और उन्हें विश्वास हो कि शिक्षक उनकी मदद के लिए हैं, और आप प्रत्येक विद्यार्थी की समझ और प्रगति के स्तर को जान सके । | DZ1: Option 3 : बहुत अच्छा है कि विद्यार्थियों को स्वतंत्र कार्य (Independent work) का समय दिया जाता है;इसके साथ ही आप कक्षा में भ्रमण भी कर रहें हैं। भ्रमण करते हुए विद्यार्थियों को सहयोग करते रहें ताकि ये सुनिश्चित किया जा सके कि वे सही दिशा मे कार्य कर रहे हैं, और उन्हें विश्वास हो कि शिक्षक उनकी मदद के लिए हैं, और आप प्रत्येक विद्यार्थी की समझ और प्रगति के स्तर को जान सके । | EA1: Option 4 : स्वतंत्र कार्य (Independent work) का समय प्रदान करने और विद्यार्थियों के साथ सक्रिय रूप से जुडने का आपका प्रयास बहुत उत्कृष्ट है; इससे विद्यार्थियों को सीखने मे सहयोग प्राप्त होता हैं एवं उनकी समझ एवं प्रगति के स्तर को जान पाते हैं। | EB1: Option 1 : विद्यार्थियों में आपस में सीखने और मिलकर समस्या-समाधान को प्रोत्साहित करने के लिए जोड़े या समूह में गतिविधि करना शामिल करें । जैसे - थिंक पेयर-शेयर, समूह कार्य आदि। | EC1: Option 2 : आप जोड़े या समूह में सीखने के अवसर देने का अच्छा उपयोग कर रहे है; इसके साथ जब विद्यार्थी एक-दूसरे के साथ मिलकर गतिविधि कर रहे हों तब आप कक्षा में भ्रमण कर उनका सहयोग एवं मार्गदर्शन करें । | ED1: Option 3 : आप जोड़े या समूह में सीखने के अवसर देने का अच्छा उपयोग कर रहे है; इसके साथ जब विद्यार्थी एक-दूसरे के साथ मिलकर गतिविधि कर रहे हों तब आप कक्षा में भ्रमण कर उनका सहयोग एवं मार्गदर्शन अवश्य करें । | EE1: Option 4 : आप विद्यार्थियों की सहभागिता एवं समझ के स्तर को बढ़ाते हुए एक दूसरे से सीखने को बढ़ावा दे रहे हैं साथ ही सक्रिय रूप से कक्षा में भ्रमण करते हुए आप विद्यार्थियों की सहायता के लिए अपनी उपलब्धता सुनिश्चित कर रहे हैं। | EF1: Option 1 : कक्षा का वातावरण सम्मानजनक और सकारात्मक बनाए रखना बहुत महत्वपूर्ण है, इससे कक्षा में विद्यार्थी सुरक्षित महसूस करते हैं; सीखने के अनुकूल वातावरण बनाने हेतु कृपया यह सुनिश्चित करें कि विद्यार्थियों के साथ सभी बातचीत सहायक और प्रोत्साहित करने वाली हो। | EG1: Option 2 : कक्षा का वातावरण सम्मानजनक और सहयोगी बनाने के लिए आप बहुत ही बढ़िया काम कर रहे हैं; इसी तरह विद्यार्थियों के विकास और सीखने के लिए सकारात्मक एवं सम्मानजनक वातावरण बनाए रखें। | EH1: Option 1 : कक्षा में सकारात्मक और प्रेरणादायी भाषा के उपयोग का आप बहुत अच्छा प्रयास कर रहे हैं; यह कक्षा का वातावरण उत्साहजनक और सहयोगी बनाने मे मदद करता है। | EI1: Option 2 : कक्षा में विद्यार्थियों को प्रेरित करने और एक सुरक्षित व सकारात्मक कक्षा संस्कृति को बढ़ावा देने के लिए उत्साहवर्धक एवं सकारात्मक भाषा का उपयोग करें। जैसे : विद्यार्थी के प्रयास की सराहना करना या सकारात्मक व्यवहार प्रदर्शित करने पर ताली बजाना आदि। | EJ1: Option 1 : एक व्यवस्थित और सीखने के लिए अनुकूल कक्षा वातावरण के लिए कक्षा के नियम और दिनचर्या/रूटीन तय करना बहुत महत्वपूर्ण हैं। व्यवस्थित कक्षा एवं बेहतर परिणामों के लिए शुरू से ही विद्यार्थियों के साथ अपेक्षाएँ तय करने और उन्हें लगातार लागू करने पर विचार करें। | EK1: Option 2 : कक्षा के नियम और दिनचर्या/रूटीन तय करने का अच्छा प्रयास शुरू किया है; इसके साथ ही यह सुनिश्चित करें कि कक्षा में व्यवस्था बनाए रखने और पूरे पाठ के दौरान विद्यार्थियों का ध्यान सुनिश्चित करने के लिए कक्षा के नियम एवं रूटीन को लगातार बढ़ावा दिया जाए और उनका नियमित पुनर्बलन किया जाए। | EL1: Option 3 : कक्षा के नियम और दिनचर्या को निर्धारित करने और लगातार पुनर्बलन करने हेतु बेहतर प्रयास कर रहे हैं, जरूरी है कि यह प्रभावी भी हो। विद्यार्थियों से नियम या रूटीन कि चर्चा अवश्य करें एवं मिलकर तय करें ताकि यह प्रभावी हो। | EM1: Option 4 : कक्षा के नियम और दिनचर्या को निर्धारित करने और लगातार पुनर्बलन करने हेतु उत्कृष्ट कार्य कर रहे हैं, यह सीखने के वातावरण को सकारात्मक और अनुशासित बनाने में मदद करता है। | EN1: Option 1 : विद्यार्थियों को रूढ़िवादिता और भेदभाव के बारे में संवेदनशील बनाकर समावेशिता को सजगता के साथ बढ़ावा देने में बहुत बढ़िया काम किया; इससे कक्षा का वातावरण सम्मानजनक और सहयोगी बनता है। | EO1: Option 2 : किसी भी तरह की रूढ़िवादिता या भेदभाव से बचना महत्वपूर्ण है; विद्यार्थियों के समक्ष सम्मानजनक और समावेशी व्यवहार का आदर्श प्रस्तुत करें जिससे वे आपका अनुसरण करते हुए इसके महत्त्व को समझ सकें और अपने व्यवहार में ला सकें। | EP1: Option 3 : सभी विद्यार्थियों के लिए समावेशी और सम्मानजनक सीखने के वातावरण को बढ़ावा देने के लिए रूढ़िवादिता और भेदभाव के मुद्दों पर सजगता के साथ ध्यान दे, बातचीत करें एवं उनकी समझ बनाएं। | EQ1: Option 1 : यह देखकर अच्छा लगा कि कक्षा का माहौल रूढ़िवादिता या भेदभाव की घटनाओं से मुक्त था, जिससे सभी विद्यार्थियों के लिए समावेशी और सम्मानजनक माहौल बना। | ER1: Option 2 : रूढ़िवादिता या भेदभाव की किसी भी घटना को तुरंत संबोधित करना अति महत्वपूर्ण है, ऐसा करने से कक्षा में एक सुरक्षित वातावरण बनेगा; कक्षा में समावेशी माहौल को बढ़ावा देने के लिए विद्यार्थियों के साथ बातचीत/दखल करने पर विचार करें। | ES1: Option 3: रूढ़िवादिता या भेदभाव की किसी भी घटना को संबोधित करने और हल करने तथा सभी विद्यार्थियों के लिए सकारात्मक और समावेशी कक्षा वातावरण सुनिश्चित करने का एक शिक्षक के तौर पर अनुकरणीय प्रयास है। | ET1: हाँ: यह देखकर बहुत अच्छा लगा कि आप के पास पाठ योजना है; यह आपकी तैयारी को दर्शाता ही है और साथ ही पाठ को व्यवस्थित तरीके से पढ़ाने में मदद करता है। | EU1: नहीं: व्यवस्थित तरीके से पढ़ाने के लिए पाठ योजना का उपयोग करने पर विचार करें और पाठ के दौरान सभी प्रमुख शिक्षण बिंदु और गतिविधियाँ प्रभावी रूप से शामिल करना सुनिश्चित करें। | EV1: पाठ योजना में सीखने के प्रतिफल (LO) शामिल करने से शिक्षक को यह स्पष्टता मिलती है कि पाठ के अंत तक उन्हें क्या सिखाना चाहिए या विद्यार्थी क्या सीख पाएंगे | EW1: TLM/शिक्षण अधिगम सामग्री (टीएलएम) का इस्तेमाल विद्यार्थियों के सीखने को आसान बनाने के लिए किया जाता है. TLM से विद्यार्थियों को ज्ञान समझने में मदद मिलती है और उनका आत्मविश्वास भी बढ़ता है. टीएलएम का इस्तेमाल करने से कक्षा में शिक्षण और सीखने का अनुभव बेहतर होता है। | EX1: यदि गतिविधियाँ शामिल नहीं की जातीं हैं या पहले से नहीं सोची जाती तो कक्षा में विद्यार्थियों की सहभागिता सुनिश्चित करना एवं शिक्षक के कार्य और विद्यार्थी के कार्य देखना मुश्किल होता है। | EY1: पाठ योजना में समझ की जांच हेतु प्रश्नों को शामिल करने से शिक्षक यह जान पाते हैं कि विद्यार्थी जिस विषय को पढ़ रहे हैं, उस पर वे कितनी समझ विकसित कर पा रहे हैं। | EZ1: गृहकार्य विद्यार्थीयों के लिए बहुत ज़रूरी होता है। यह उन्हें पढ़े गए विषयों को दोहराने और अभ्यास करने का मौका देता है और गृहकार्य से विद्यार्थियों में स्व-अध्ययन की क्षमता भी विकसित होती है। | FA1: पाठ योजना में कुछ मुख्य घटक जैसे सीखने के प्रतिफल, आवश्यक सामग्री, गतीविधियों का विवरण, समझ की जांच एवं गृहकार्य को सम्मिलित करना आवश्यक है जिससे कक्षा में उसे प्रभावी रूप से सम्मिलित किया जा सके। | FB1: Option 1: कक्षा का संचालन पाठ योजना के अनुसार करने का आपका प्रयास अच्छा हैं; यह सुनिश्चित करता है कि पाठ योजना के सभी उद्देश्य और गतिविधियाँ प्रभावी और व्यवस्थित रूप से शामिल की गई हैं। | FC1: Option 2: पाठ संचालन आंशिक रूप से पाठ योजना के अनुरूप था; यह सुनिश्चित करने का प्रयास करें कि सत्र के दौरान सभी प्रमुख तत्वों और उद्देश्यों को पूरी तरह शामिल किए गए हैं। | FD1: Option 3: पाठ संचालन, पाठ योजना के अनुरूप नहीं था; सभी निर्धारित उद्देश्यों की प्राप्ति सुनिश्चित करने के लिए व्यवस्थित पाठ योजना निर्माण एवं पढ़ाने के दौरान योजना का पालन करना बहुत आवश्यक हैं। | FE1: यदि सभी चयनित हैं: बहुत अच्छा कार्य! पढ़ाए गए पाठ में लगभग सभी महत्वपूर्ण घटक शामिल थे जैसे- विषय से संबंधित गतिविधियाँ, समझ की जांच के लिए प्रश्न, गृहकार्य। | FF1: यदि केवल एक या दो विकल्प चुने गए हैं: एक पाठ को अच्छे से पढ़ाते समय उसमें विषय से संबंधित गतिविधियाँ, समझ की जांच के लिए प्रश्न, गृहकार्य जैसे घटक शामिल होने चाहिए। | FG1: अगर उपरोक्त में से कोई भी नहीं - एक पाठ को अच्छे से पढ़ाते समय उसमें विषय से संबंधित गतिविधियाँ, TLM का उपयोग, समझ की जांच के लिए प्रश्न, गृहकार्य जैसे घटक शामिल होने चाहिए। | FH1: Option 1: बिना किसी देरी के नियमित रूप से जाँची जाती है: यह बहुत अच्छा काम किया गया है कि विद्यार्थियों की नोटबुक को तुरंत सुधारा जाता है; इससे उनके सीखने मे सहायता करने के लिए तुरंत सुधारात्मक प्रतिक्रिया देने में मदद मिलती है। | FI1: Option 2: सुनिश्चित करें कि विद्यार्थियों की नोटबुक नियमित रूप से उचित समय-सीमा में जांची जाती है, क्योंकि समय पर जाँचना उनके सीखने की प्रगति के लिए महत्वपूर्ण है। | FJ1: Option 3 : सुनिश्चिiत करें कि विद्यार्थियों की नोटबुक को अवश्य जाँचा जाए, और इस प्रक्रिया को नियमित रूप से उचित समय-सीमा में किया जाए, क्योंकि समय पर जाँचना उनके सीखने की प्रगति के लिए महत्वपूर्ण है। | FK1: Option 1: विद्यार्थियों के काम में त्रुटियों की पहचान करना और उन्हें सुधारना उनकी समझ और सुधार हेतु सहायता करने के लिए महत्वपूर्ण है। स्पष्ट सुधार के बिन्दु बताना एवं समझाना सुनिश्चित करें। | FL1: Option 2: त्रुटियों की पहचान की जा रही है, विद्यार्थियों को उनके सीखने में मार्गदर्शन करने और गलतियों को दोहराने से बचने में मदद करने के लिए उनके सुधार बिन्दु बताना एवं उन्हें समझाना भी महत्वपूर्ण है। | FM1: Option 3: अधिकांश त्रुटियों की पहचान करने और उन्हें सुधारने का कार्य उत्कृष्ट हैं ; यह विद्यार्थियों के सीखने में सहायता करता है और उन्हें पाठ्य सामग्री पर अपनी समझ को बेहतर बनाने में मदद करता है। | FN1: Option 1: विद्यार्थियों के विकास के लिए लिखित प्रतिक्रिया देना महत्वपूर्ण है; सुनिश्चित करें कि रचनात्मक टिप्पणियाँ शामिल हों जो विद्यार्थियों को उनके काम को बेहतर बनाने में मार्गदर्शन करें। | FO1: Option 2: सामान्य टिप्पणियाँ सुधार के लिए पर्याप्त मार्गदर्शन प्रदान नहीं करती हैं; विशिष्ट और रचनात्मक फीडबैक देने का लक्ष्य रखें जिससे विद्यार्थियों को अपने मजबूत पक्ष एवं सुधार के क्षेत्रों के बारे मे जानकारी प्राप्त होती हैं। | FP1: Option 3: विशिष्ट और करने योग्य प्रतिक्रिया प्रदान करने में बहुत अच्छा कार्य; इससे विद्यार्थियों को अपने मजबूत पक्ष एवं सुधार के क्षेत्रों के बारे मे जानकारी प्राप्त होती हैं। | FQ1: Option 1 : नोटबुकको साफ - सुथरा रखनेऔर प्रस्तुति पर फीडबैक देने पर विचार करें; क्योंकि यह विद्यार्थियों को उनके काम पर गर्व करने और काम को प्रस्तुत करने के कौशल विकसित करने के लिए प्रोत्साहित करता है। | FR1: Option 2 : विद्यार्थियों को स्पष्ट, साफ- सुथरा और व्यवस्थित काम के महत्व को समझने में मदद करने के लिए नोटबुक की साफ-सफाई और प्रस्तुति पर लगातार फीडबैक देना महत्वपूर्ण है। | FS1: Option 3 : नोटबुकको साफ- सुथरा रखनेऔर प्रस्तुति पर लगातार फीडबैक देने में बहुत बढ़िया काम किया है; इससे विद्यार्थियों को उनके काम में स्पष्टता और व्यवस्थित होने के महत्व को समझने में मदद मिलती है। | FT1: Option 1 or 2: पठन-पाठन में नोटबुक एक महत्वपूर्ण संसाधन है, क्योंकि इससे विद्यार्थियों को विषयों को समझने में मदद मिलती है। नोटबुक में लिखे गए नोट्स, विद्यार्थियों को बाद में पढ़ने और अभ्यास करने में मदद करते हैं। साथ ही, नोटबुक से विद्यार्थियों के विचारों को व्यवस्थित करने में भी मदद मिलती है। | FU1: Option 3: अपनी कक्षा में आप अधिकतम विद्यार्थियों के द्वारा नोटबुक में कार्य सुनिश्चित कर रहे हैं, आपके प्रयास सराहनीय हैं और आप ऐसे ही सुनिश्चित करते रहें की सभी विद्यार्थी नोटबुक में नियम से कार्य करते रहें | FV1: कक्षा मे शिक्षण के दौरान विषय से जुड़ी पुस्तकें विद्यार्थियों को विषय वस्तु से जुड़ाव बनाने मे मदद करती हैं , इसलिए विद्यार्थियों को विषय से जुड़ी पुस्तकें अपने पास रखने के लिए प्रोत्साहित करें। | FW1: सन्दर्भ पोस्टर्स, माइंड मैप्स, फ्लोचार्ट्स और डायग्राम जैसे चार्ट जटिल विचारों को सरल तरीके से प्रस्तुत करते हैं, जिससे छात्रों को समझने और याद रखने में मदद मिलती है। ये त्वरित संदर्भ के रूप में काम करते हैं, मुख्य अवधारणाओं को मजबूत करते हैं और सक्रिय अधिगम को प्रोत्साहित करते हैं। | FX1: पुराने चार्ट और पोस्टर्स को नियमित रूप से अपडेट करें, ताकि ये वर्तमान पाठ्यक्रम से प्रासंगिक रहें एवं इनमें दी गयी जानकारी देखी/समझी जा सकती है। | FY1: When either option ii or iii is selected -इस प्रक्रिया में विद्यार्थियों के द्वारा बनाए गए चार्ट और सामग्री से उनकी कक्षा में सहभागिता और जुड़ाव बढ़ता है, साथ ही अवधारणा पर समझ भी बेहतर होती है। | FZ1: Option 1 - कक्षा में मौजूद चार्ट/पोस्टर प्रासंगिक विषयों पर हैं जिन्हें वर्तमान में कक्षा में शामिल/पढ़ाया जा रहा है। यह कक्षा के सीखने के वातावरण को और बेहतर बनाता है। | GA1: Option 2 - कक्षा में मौजूद चार्ट/पोस्टर प्रासंगिक विषयों पर हैं यह सरहनीय है, लेकिन इन्हें वर्तमान में कक्षा में शामिल/पढ़ाया जाना भी सुनिश्चित करें। | GB1: Option 3- कक्षा में मौजूद चार्ट/पोस्टर प्रासंगिक विषयों पर होना और इन्हें वर्तमान में कक्षा में शामिल/पढ़ाया जाना सुनिश्चित करें। यह कक्षा के सीखने के वातावरण को और बेहतर बनाता है। | GC1: शिक्षिका/शिक्षक के साथ साझा किए गए 3 सकारात्मक बिन्दु (फीडबैक) लिखे | GD1: शिक्षिका/शिक्षक के साथ साझा किए गए 3 रचनात्मक बिन्दु (स्कोप/फीडबैक) लिखे | GE1: क्या आपको अपने प्रोफेशनल डेवलपमेंट मे किसी सहायता की आवश्यता है? यदि हाँ तो विस्तार मे बताए (पीपुल की और से) - | GF1: शिक्षक या विध्यालय से जुड़ी कोई अन्य जानकारी | GG1: संभाग | GH1: संभाग | GI1: जिला | GJ1: ब्लॉक | GK1: मास्टर ट्रैनर का नाम | GL1: विषय | GM1: _id | GN1: _uuid | GO1: _submission_time | GP1: _validation_status | GQ1: _notes | GR1: _status | GS1: _submitted_by | GT1: __version__ | GU1: _tags | GV1: meta/rootUuid | GW1: _index
A2: 45891.369 | B2: 45891.391 | H2: 45891 | I2: Amit Pradhan | L2: Yes | M2: Dindori | N2: Mehandwani | O2: 23411509502 | P2: Shama Anjum Qureshi | Q2: Science | R2: हाँ | U2: महिला | Y2: कक्षा 8 | Z2: 0 | AA2: 0 | AB2: 1 | AC2: 300 | AD2: 300 | AE2: 300 | AF2: Teaching | AG2: विज्ञान | AH2: 0 | AI2: 0 | AJ2: 0 | AK2: 0 | AL2: 0 | AM2: 0 | AN2: 1 | AO2: 0 | AP2: 0 | AR2: विज्ञान | AS2: 18 | AT2: 11 | AU2: iv.शिक्षक कक्षा के प्रारंभ में विद्यार्थियों का स्वागत करते हैं, उनका हाल चाल लेते हुए विषय पर हुक/चर्चा के माध्यम से उनका विषय वस्तु के साथ जुड़ाव बनाकर सकारात्मक शुरुआत करते हैं। | AV2: i. व्याख्यान करते हैं। | AW2: 1 | AX2: 0 | AY2: 0 | AZ2: 0 | BA2: 0 | BC2: ii.10% - 40% विद्यार्थियों की सहभागिता है और शिक्षक ही अधिकांशतः बोल रहे हैं। | BD2: i.हुक का प्रयोग | BE2: 1 | BF2: 0 | BG2: 0 | BH2: 0 | BI2: 0 | BJ2: 0 | BK2: iii.शिक्षक बंद और खुले-छोर (close & open-ended questions) वाले प्रश्नों को मिश्रित रूप से पूछते हैं | BL2: i.कोई समय नहीं दिया गया, मुख्यतः तत्काल प्रतिक्रिया मांगी गई। | BM2: i.शिक्षक अधिकांशत: प्रश्नों पर विद्यार्थियों से सामूहिक प्रतिक्रियाएँ लेते हैं। | BN2: i. अधिकांशतः हाँ/ना में सामूहिक उत्तर लेना | BO2: i.शिक्षक स्वतंत्र कार्य के लिए विद्यार्थियों को समय नहीं देते हैं। | BP2: i.शिक्षक विद्यार्थियों को समूह कार्य के अवसर प्रदान नहीं करते हैं। | BQ2: ii.नहीं | BS2: ii.नहीं | BT2: i.कक्षा के नियम या दिनचर्या/रूटीन निर्धारित नहीं हैं। | BU2: iii.नहीं देखा गया (शिक्षक ने न तो रूढ़िवादिता या भेदभाव को बढ़ावा दिया/अभ्यास किया और न ही विद्यार्थियों को रूढ़िवादिता या भेदभाव के बारे में जागरूक किया) | BV2: i.अवलोकन के दौरान रूढ़िवादिता या भेदभाव की कोई घटना नहीं देखी गई। | BW2: ii.नहीं | CF2: iii.समझ की जाँच (CFU) प्रश्न | CG2: 0 | CH2: 0 | CI2: 1 | CJ2: 0 | CK2: 0 | CL2: 3.कभी जाँची नहीं जाती | CM2: 1.त्रुटियों की न तो पहचान की जाती है और न ही उन्हें सुधारा जाता है। | CN2: 1.कोई फीडबैक नहीं दिया गया। | CO2: 1.नोटबुक को साफ़ सुथरा रखने और प्रस्तुतिकरण पर कोई टिप्पणी या फीडबैक नहीं। | CP2: i.अवलोकन के दौरान विषय-विशिष्ट नोटबुक नहीं पायी गईं। | CQ2: 6 | CR2: ii.नहीं | CV2: ii.कोई दो विद्यार्थी धाराप्रवाह के साथ पढ़ पा रहें हैं। | CW2: ii.कोई दो विद्यार्थीपढ़े हुए पैराग्राफ का कम से कम 70% समझ पा रहें हैं। | CX2: ii.किन्ही दो विद्यार्थियों ने बिना किसी त्रुटि के लिखा है। | GC2: 1) Ma'am asked a lot of questions during her teaching, both open and closed. I appreciated it. 2) Ma'am taught with the local context in mind, used words like गंठी , फावड़ा एंड तागाडीया 3) Gave individual attention to one of the children who was not getting involved in the teaching process. | GD2: 1) Using Cold Calling in the classroom 2) Asking more CFUs and giving wait time for students to answer [ gave only 2 pointers ] | GE2: - | GF2: Students from Dindori side could not come till August as the connecting bridge had been damaged. In Science , the course had not yet been started. The school did not have electricity connection- for grade 8 , when the weather is not sunny, the classroom gets pretty dark. | GM2: 694202711 | GN2: b7df1b3d-9a55-490f-8c6a-e28a68f09caf | GO2: 45891.162 | GR2: submitted_via_web | GT2: vVLoBVrPnDmiCZ8fxF6Nin | GV2: uuid:b7df1b3d-9a55-490f-8c6a-e28a68f09caf | GW2: 1
A3: 45891.533 | B3: 45891.563 | C3: 23.06621 75.853373 434.793701171875 100 | D3: 23.06621 | E3: 75.853373 | F3: 434.7937 | G3: 100 | H3: 45891 | I3: Rahul Kumar | L3: Yes | M3: Ujjain | N3: Ujjain Rural | O3: 23210104102 | P3: Bhupendra Singh Rathore | Q3: Science | R3: हाँ | U3: पुरुष | Y3: कक्षा 7 | Z3: 0 | AA3: 1 | AB3: 0 | AC3: 25 | AD3: 10 | AE3: 25 | AF3: Teaching | AG3: अन्य | AH3: 0 | AI3: 0 | AJ3: 0 | AK3: 0 | AL3: 0 | AM3: 0 | AN3: 0 | AO3: 0 | AP3: 1 | AQ3: NA | AR3: विज्ञान | AS3: 47 | AT3: 42 | AU3: iii.शिक्षक कक्षा की शरुआत रोचक तरीके से हुक तकनीक के उपयोग से करते है (हुक: एक तकनीक जो विद्यार्थियों को आकर्षित करने के लिए पाठ का परिचय कहानी, वस्तुओं, तथ्य और प्रश्नों के माध्यम से किया जाता है। यह 30 सेकण्ड से 3 मिनट का एक छोटा भाग होता है।) | AV3: i. व्याख्यान करते हैं। iii. टीएलएम का उपयोग करते हैं (पाठ्यपुस्तक और ब्लैक/वाइट बोर्ड के अलावा) iv. गतिविधि या खेल | AW3: 1 | AX3: 0 | AY3: 1 | AZ3: 1 | BA3: 0 | BC3: ii.10% - 40% विद्यार्थियों की सहभागिता है और शिक्षक ही अधिकांशतः बोल रहे हैं। | BD3: i.हुक का प्रयोग | BE3: 1 | BF3: 0 | BG3: 0 | BH3: 0 | BI3: 0 | BJ3: 0 | BK3: iii.शिक्षक बंद और खुले-छोर (close & open-ended questions) वाले प्रश्नों को मिश्रित रूप से पूछते हैं | BL3: iii.समय दिया गया और अधिकांशतः सोचने के लिए पर्याप्त था। | BM3: i.शिक्षक अधिकांशत: प्रश्नों पर विद्यार्थियों से सामूहिक प्रतिक्रियाएँ लेते हैं। | BN3: ii.हाँ, अधिकांशतः कुछ बुनियादी समझ की जाँच की तकनीक (हाथ उठाना, अंगूठा दिखाना, आदि) का प्रयोग किया गया | BO3: iv.शिक्षक स्वतंत्र कार्य के लिए विद्यार्थियों को समय देते हैं और विद्यार्थियों के कार्य की जाँच करने और उनकी सहायता करने के लिए कक्षा में भ्रमण भी करते हैं। | BP3: i.शिक्षक विद्यार्थियों को समूह कार्य के अवसर प्रदान नहीं करते हैं। | BQ3: ii.नहीं | BS3: i.हाँ | BT3: iv.कक्षा के नियम या दिनचर्या/रूटीन निर्धारित हैं और आवश्यकता अनुसार लगातार सुदृढ़ किए जाते हैं एवं प्रभावी भी हैं। | BU3: iii.नहीं देखा गया (शिक्षक ने न तो रूढ़िवादिता या भेदभाव को बढ़ावा दिया/अभ्यास किया और न ही विद्यार्थियों को रूढ़िवादिता या भेदभाव के बारे में जागरूक किया) | BV3: i.अवलोकन के दौरान रूढ़िवादिता या भेदभाव की कोई घटना नहीं देखी गई। | BW3: i.हाँ | BX3: ii.आवश्यक सामग्री (जैसे: टीएलएम) iii.गतिविधियों का विवरण (जैसे: प्रयोग, खेल, चर्चा, समूह कार्य आदि) iv.समझ की जांच (CFU) हेतु प्रश्न v.गृहकार्य | BY3: 0 | BZ3: 1 | CA3: 1 | CB3: 1 | CC3: 1 | CD3: 0 | CE3: i.हाँ, पूरी तरह से | CF3: i.TLM का उपयोग किया ii.विषय से संबंधित गतिविधियाँ iii.समझ की जाँच (CFU) प्रश्न iv.गृहकार्य देना | CG3: 1 | CH3: 1 | CI3: 1 | CJ3: 1 | CK3: 0 | CL3: 1. नियमित रूप से बिना देरी के तुरंत जाँची जाती है। | CM3: 3.अधिकांश त्रुटियों की पहचान की जाती है और उन्हें सुधारा जाता है। | CN3: 2.“अच्छा” या “ठीक है” जैसी सामान्य टिप्पणियाँ लिखी गईं। | CO3: 1.नोटबुक को साफ़ सुथरा रखने और प्रस्तुतिकरण पर कोई टिप्पणी या फीडबैक नहीं। | CP3: iii.50% से अधिक विद्यार्थी विषय-विशिष्ट नोटबुक में काम करते हैं। | CQ3: 8 | CR3: ii.नहीं | CV3: i.सभी तीन विद्यार्थी धाराप्रवाह के साथ पढ़ पा रहें हैं। | CW3: i.सभी तीन विद्यार्थी पढ़े हुए पैराग्राफ का कम से कम 70% समझ पा रहें हैं। | CX3: i.सभी तीन विद्यार्थियों ने बिना किसी त्रुटि के लिखा है। | GC3: 1 - प्रशिक्षण में पाठ योजना में बताये गये सभी अवयव को शामिल किया गया । 2 - हुक से कक्षा की शुरुआत हुई । 3 - कक्षा कक्ष में आस पास के वस्तुओ से प्रयोगात्मक तरीके से पढाया गया । | GD3: 1 - समझ की जाँच के प्रश्न पर कार्य किया जा सकता है । 2 - हुक को कक्षा के प्रारंभ में करना चाहिए । | GE3: ध्वनि नामक पाठ पर वीडियोज उपलब्ध हो जाये तो बच्चो को पढाने में आसानी रहेगी | GF3: NA | GM3: 694263266 | GN3: 735cd1bb-c355-48ef-be2e-5c1fb9959cec | GO3: 45891.334 | GR3: submitted_via_web | GT3: vVLoBVrPnDmiCZ8fxF6Nin | GV3: uuid:735cd1bb-c355-48ef-be2e-5c1fb9959cec | GW3: 2
A4: 45891.492 | B4: 45891.57 | H4: 45891 | I4: Dharmendra Mishra | L4: Yes | M4: Chhatarpur | N4: Ishanagaar | O4: 22390501401 | P4: Manoj Jain | Q4: Social Science | R4: हाँ | U4: पुरुष | Y4: कक्षा 6 | Z4: 1 | AA4: 0 | AB4: 0 | AC4: 324 | AD4: 156 | AE4: 156 | AF4: Teaching | AG4: सामाजिक विज्ञान | AH4: 0 | AI4: 0 | AJ4: 0 | AK4: 0 | AL4: 0 | AM4: 0 | AN4: 0 | AO4: 1 | AP4: 0 | AR4: हिन्दी | AS4: 50 | AT4: 30 | AU4: iii.शिक्षक कक्षा की शरुआत रोचक तरीके से हुक तकनीक के उपयोग से करते है (हुक: एक तकनीक जो विद्यार्थियों को आकर्षित करने के लिए पाठ का परिचय कहानी, वस्तुओं, तथ्य और प्रश्नों के माध्यम से किया जाता है। यह 30 सेकण्ड से 3 मिनट का एक छोटा भाग होता है।) | AV4: i. व्याख्यान करते हैं। ii. विद्यार्थियों से पाठ के कुछ हिस्सों को पढ़ने के लिए कहते हैं। | AW4: 1 | AX4: 1 | AY4: 0 | AZ4: 0 | BA4: 0 | BC4: ii.10% - 40% विद्यार्थियों की सहभागिता है और शिक्षक ही अधिकांशतः बोल रहे हैं। | BD4: i.हुक का प्रयोग | BE4: 1 | BF4: 0 | BG4: 0 | BH4: 0 | BI4: 0 | BJ4: 0 | BK4: ii.शिक्षक केवल बंद-छोर वाले प्रश्न (close ended) पूछते हैं | BL4: i.कोई समय नहीं दिया गया, मुख्यतः तत्काल प्रतिक्रिया मांगी गई। | BM4: ii.शिक्षक अधिकांशत: प्रश्नों पर उन विद्यार्थियों से प्रतिक्रियाएँ लेते हैं जो हाथ उठाते हैं/ कुछ विद्यार्थियों से ही उत्तर लेते हैं । | BN4: iv.समझ की जांच नहीं की गई | BO4: ii.शिक्षक स्वतंत्र कार्य के लिए विद्यार्थियों को समय देते हैं, लेकिन विद्यार्थियों के कार्य की जाँच करने और उनकी सहायता करने के लिए कक्षा में भ्रमण नहीं करते हैं। | BP4: i.शिक्षक विद्यार्थियों को समूह कार्य के अवसर प्रदान नहीं करते हैं। | BQ4: ii.नहीं | BS4: i.हाँ | BT4: i.कक्षा के नियम या दिनचर्या/रूटीन निर्धारित नहीं हैं। | BU4: iii.नहीं देखा गया (शिक्षक ने न तो रूढ़िवादिता या भेदभाव को बढ़ावा दिया/अभ्यास किया और न ही विद्यार्थियों को रूढ़िवादिता या भेदभाव के बारे में जागरूक किया) | BV4: i.अवलोकन के दौरान रूढ़िवादिता या भेदभाव की कोई घटना नहीं देखी गई। | BW4: ii.नहीं | CF4: iii.समझ की जाँच (CFU) प्रश्न iv.गृहकार्य देना | CG4: 0 | CH4: 0 | CI4: 1 | CJ4: 1 | CK4: 0 | CL4: 1. नियमित रूप से बिना देरी के तुरंत जाँची जाती है। | CM4: 3.अधिकांश त्रुटियों की पहचान की जाती है और उन्हें सुधारा जाता है। | CN4: 1.कोई फीडबैक नहीं दिया गया। | CO4: 1.नोटबुक को साफ़ सुथरा रखने और प्रस्तुतिकरण पर कोई टिप्पणी या फीडबैक नहीं। | CP4: i.अवलोकन के दौरान विषय-विशिष्ट नोटबुक नहीं पायी गईं। | CQ4: 28 | CR4: i.हाँ | CS4: i.अधिकतर नए | CT4: i.अधिकतर विद्यार्थियों द्वारा बनाए गए | CU4: iii.चार्ट/पोस्टर कक्षा से संबंधित हैं (उदाहरण के लिए कक्षा के नियम/जन्मदिन/समय-सारणी) लेकिन पढ़ाए जा रहे विषयों से प्रासंगिक नहीं हैं।) | CV4: i.सभी तीन विद्यार्थी धाराप्रवाह के साथ पढ़ पा रहें हैं। | CW4: i.सभी तीन विद्यार्थी पढ़े हुए पैराग्राफ का कम से कम 70% समझ पा रहें हैं। | CX4: i.सभी तीन विद्यार्थियों ने बिना किसी त्रुटि के लिखा है। | GC4: 1. अलग-अलग शिक्षण आवश्यकताओं को पूरा करने के लिए विविध शिक्षण विधियों/तरीकों का उत्कृष्ट उपयोग किया जा रहा है; समग्र सीख और सहभागिता आधारित शिक्षण को इसी तरह जारी रखें। 2. कक्षा का वातावरण सम्मानजनक और सहयोगी बनाने के लिए आप बहुत ही बढ़िया काम कर रहे हैं; इसी तरह विद्यार्थियों के विकास और सीखने के लिए सकारात्मक एवं सम्मानजनक वातावरण बनाए रखें। 3. यह देखकर अच्छा लगा कि कक्षा का माहौल रूढ़िवादिता या भेदभाव की घटनाओं से मुक्त था, जिससे सभी विद्यार्थियों के लिए समावेशी और सम्मानजनक माहौल बना। | GD4: 1. व्यवस्थित तरीके से पढ़ाने के लिए पाठ योजना का उपयोग करने पर विचार करें और पाठ के दौरान सभी प्रमुख शिक्षण बिंदु और गतिविधियाँ प्रभावी रूप से शामिल करना सुनिश्चित करें। 2. आपने पढ़ाते समय कुछ विद्यार्थियों को शामिल करने का अच्छा प्रयास किया; शिक्षण में अधिकतम विद्यार्थियों को शामिल करने के लिए आपको सहभागिता बढ़ाने के तरीकों को अपनाना चाहिए। (जैसे कोल्ड कालिंग, TPS, चर्चा आदि) 3. एक व्यवस्थित और सीखने के लिए अनुकूल कक्षा वातावरण के लिए कक्षा के नियम और दिनचर्या/रूटीन तय करना बहुत महत्वपूर्ण हैं। व्यवस्थित कक्षा एवं बेहतर परिणामों के लिए शुरू से ही विद्यार्थियों के साथ अपेक्षाएँ तय करने और उन्हें लगातार लागू करने पर विचार करें। | GE4: नहीं | GM4: 694266266 | GN4: c5f5a7d2-084e-4c30-9db3-3258092a3d4a | GO4: 45891.341 | GR4: submitted_via_web | GT4: vVLoBVrPnDmiCZ8fxF6Nin | GV4: uuid:c5f5a7d2-084e-4c30-9db3-3258092a3d4a | GW4: 3
A5: 45891.576 | B5: 45922.694 | H5: 45891 | I5: Aishwarya Yadav | L5: No | M5: Betul | N5: Betul | O5: 23350305003 | S5: गणित | U5: पुरुष | V5: जगदीश झाड़े | W5: BQ5822 | X5: हाँ | Y5: कक्षा 7 | Z5: 0 | AA5: 1 | AB5: 0 | AC5: 192 | AD5: 192 | AE5: 192 | AF5: Teaching | AG5: हिन्दी इंग्लिश गणित विज्ञान सामाजिक विज्ञान | AH5: 1 | AI5: 1 | AJ5: 0 | AK5: 0 | AL5: 0 | AM5: 1 | AN5: 1 | AO5: 1 | AP5: 0 | AR5: गणित | AS5: 20 | AT5: 18 | AU5: i.शिक्षक कक्षा की शुरुआत, बिना किसी भूमिका के सीधे पढ़ाने से शुरू कर देते हैं। | AV5: ii. विद्यार्थियों से पाठ के कुछ हिस्सों को पढ़ने के लिए कहते हैं। | AW5: 0 | AX5: 1 | AY5: 0 | AZ5: 0 | BA5: 0 | BC5: iii.40% या उससे अधिक (अपेक्षा अनुरूप) विद्यार्थियों की सहभागिता है। | BD5: iii.समूह चर्चा v.विद्यार्थी के कार्यों (अकादमिक/गैर अकादमिक) पर रचनात्मक फीडबैक (Constructive Feedback) | BE5: 0 | BF5: 0 | BG5: 1 | BH5: 0 | BI5: 1 | BJ5: 0 | BK5: ii.शिक्षक केवल बंद-छोर वाले प्रश्न (close ended) पूछते हैं | BL5: iii.समय दिया गया और अधिकांशतः सोचने के लिए पर्याप्त था। | BM5: iii.शिक्षक अधिकांशत: प्रश्नों पर प्रतिक्रिया हेतु रेन्डम/बिना किसी क्रम के प्रश्न पूछने की तकनीक का उपयोग करते हैं (जैसे कोल्ड कॉलिंग)। | BN5: ii.हाँ, अधिकांशतः कुछ बुनियादी समझ की जाँच की तकनीक (हाथ उठाना, अंगूठा दिखाना, आदि) का प्रयोग किया गया | BO5: iv.शिक्षक स्वतंत्र कार्य के लिए विद्यार्थियों को समय देते हैं और विद्यार्थियों के कार्य की जाँच करने और उनकी सहायता करने के लिए कक्षा में भ्रमण भी करते हैं। | BP5: iv.शिक्षक समूह में सीखने के अवसर प्रदान करते हैं और विद्यार्थियों के कार्य की जाँच करने और उनकी सहायता के लिए कक्षा में भ्रमण करते हैं। | BQ5: ii.नहीं | BS5: i.हाँ | BT5: ii.कक्षा के नियम या दिनचर्या/ रूटीन निर्धारित हैं, लेकिन नियमित रूप से सुदृढ़ नहीं किए जाते हैं (आवश्यकता होने पर भी)। | BU5: iii.नहीं देखा गया (शिक्षक ने न तो रूढ़िवादिता या भेदभाव को बढ़ावा दिया/अभ्यास किया और न ही विद्यार्थियों को रूढ़िवादिता या भेदभाव के बारे में जागरूक किया) | BV5: i.अवलोकन के दौरान रूढ़िवादिता या भेदभाव की कोई घटना नहीं देखी गई। | BW5: ii.नहीं | CF5: iii.समझ की जाँच (CFU) प्रश्न iv.गृहकार्य देना | CG5: 0 | CH5: 0 | CI5: 1 | CJ5: 1 | CK5: 0 | CL5: 1. नियमित रूप से बिना देरी के तुरंत जाँची जाती है। | CM5: 3.अधिकांश त्रुटियों की पहचान की जाती है और उन्हें सुधारा जाता है। | CN5: 1.कोई फीडबैक नहीं दिया गया। | CO5: 2.नोटबुक को साफ सुथरा रखने और प्रस्तुतिकरण पर अनियमित टिप्पणी या फीडबैक। | CP5: iii.50% से अधिक विद्यार्थी विषय-विशिष्ट नोटबुक में काम करते हैं। | CQ5: 18 | CR5: ii.नहीं | CV5: i.सभी तीन विद्यार्थी धाराप्रवाह के साथ पढ़ पा रहें हैं। | CW5: i.सभी तीन विद्यार्थी पढ़े हुए पैराग्राफ का कम से कम 70% समझ पा रहें हैं। | CX5: ii.किन्ही दो विद्यार्थियों ने बिना किसी त्रुटि के लिखा है। | GC5: कक्षा में बच्चों को सक्रिय करने हेतु आवश्यकतानुसार तकनीकों का नियमित उपयोग करना, कक्षा कक्ष में नियमों का निर्धारण कर नियमित उपयोग करना, बच्चों के कार्यों पर रचनात्मक फीडबैक प्रदान करना | GD5: आप अपनी कक्षा को बहुत अच्छे से सक्रिय बनाए हुए हैं बच्चों के साथ इसी प्रकार से शैक्षिक कार्य कराते रहिए। बच्चों के कार्यों को अपनियमित रूप से जांचते हैं इसमें सुधारात्मक बिंदुओं को भी एड कर लें तो बच्चों को अपनी गलती सुधार ने ओर इसे समझने में आसानी हो जाएगी। बच्चों के कार्यों का बच्चों से आंकलन करने की आपकी रणनीति बहुत ही प्रभावी है। | GE5: नहीं | GM5: 694295044 | GN5: ca2f701e-e632-4bd7-a9be-4c01094860bf | GO5: 45891.405 | GR5: submitted_via_web | GT5: vVLoBVrPnDmiCZ8fxF6Nin | GV5: uuid:cba1295b-29bc-4772-9175-869bdb61f9b2 | GW5: 4
A6: 45891.719 | B6: 45891.785 | C6: 19.076029 72.865921 0.0 92 | D6: 19.076029 | E6: 72.865921 | F6: 0 | G6: 92 | H6: 45891 | I6: Pushpendra Singh | L6: No | M6: Mandla | N6: Beejadandi | O6: 23421400102 | S6: गणित | U6: पुरुष | V6: Devasant Patkar | W6: BQ8331 | X6: हाँ | Y6: कक्षा 6 | Z6: 1 | AA6: 0 | AB6: 0 | AC6: 13 | AD6: 13 | AE6: 13 | AF6: Teaching | AG6: गणित विज्ञान | AH6: 0 | AI6: 0 | AJ6: 0 | AK6: 0 | AL6: 0 | AM6: 1 | AN6: 1 | AO6: 0 | AP6: 0 | AR6: गणित | AS6: 11 | AT6: 10 | AU6: i.शिक्षक कक्षा की शुरुआत, बिना किसी भूमिका के सीधे पढ़ाने से शुरू कर देते हैं। | AV6: i. व्याख्यान करते हैं। iii. टीएलएम का उपयोग करते हैं (पाठ्यपुस्तक और ब्लैक/वाइट बोर्ड के अलावा) | AW6: 1 | AX6: 0 | AY6: 1 | AZ6: 0 | BA6: 0 | BC6: ii.10% - 40% विद्यार्थियों की सहभागिता है और शिक्षक ही अधिकांशतः बोल रहे हैं। | BD6: vi.इनमें से कोई नहीं देखा गया | BE6: 0 | BF6: 0 | BG6: 0 | BH6: 0 | BI6: 0 | BJ6: 1 | BK6: iii.शिक्षक बंद और खुले-छोर (close & open-ended questions) वाले प्रश्नों को मिश्रित रूप से पूछते हैं | BL6: i.कोई समय नहीं दिया गया, मुख्यतः तत्काल प्रतिक्रिया मांगी गई। | BM6: i.शिक्षक अधिकांशत: प्रश्नों पर विद्यार्थियों से सामूहिक प्रतिक्रियाएँ लेते हैं। | BN6: i. अधिकांशतः हाँ/ना में सामूहिक उत्तर लेना | BO6: i.शिक्षक स्वतंत्र कार्य के लिए विद्यार्थियों को समय नहीं देते हैं। | BP6: i.शिक्षक विद्यार्थियों को समूह कार्य के अवसर प्रदान नहीं करते हैं। | BQ6: ii.नहीं | BS6: ii.नहीं | BT6: i.कक्षा के नियम या दिनचर्या/रूटीन निर्धारित नहीं हैं। | BU6: iii.नहीं देखा गया (शिक्षक ने न तो रूढ़िवादिता या भेदभाव को बढ़ावा दिया/अभ्यास किया और न ही विद्यार्थियों को रूढ़िवादिता या भेदभाव के बारे में जागरूक किया) | BV6: i.अवलोकन के दौरान रूढ़िवादिता या भेदभाव की कोई घटना नहीं देखी गई। | BW6: ii.नहीं | CF6: iii.समझ की जाँच (CFU) प्रश्न | CG6: 0 | CH6: 0 | CI6: 1 | CJ6: 0 | CK6: 0 | CL6: 3.कभी जाँची नहीं जाती | CM6: 1.त्रुटियों की न तो पहचान की जाती है और न ही उन्हें सुधारा जाता है। | CN6: 1.कोई फीडबैक नहीं दिया गया। | CO6: 1.नोटबुक को साफ़ सुथरा रखने और प्रस्तुतिकरण पर कोई टिप्पणी या फीडबैक नहीं। | CP6: i.अवलोकन के दौरान विषय-विशिष्ट नोटबुक नहीं पायी गईं। | CQ6: 10 | CR6: ii.नहीं | CV6: iv.कोई विद्यार्थी धाराप्रवाह के साथ नहीं पढ़ पा रहा है। | CW6: iv. कोई भी विद्यार्थी पढ़े हुए पैराग्राफ का कम से कम 70% नही समझ पा रहा है। | CX6: iv.कोई विद्यार्थी नहीं लिख पाया या लेखन में त्रुटि है। | GC6: आपने प्रश्न के अलग-अलग प्रकारों का संतुलित उपयोग करने का उत्कृष्ट प्रयास किया; कक्षा में पढ़ाते समय इसी तरह विद्यार्थियों द्वारा विचारों की अभिव्यक्ति एवं सक्रिय भागीदारी को बढ़ाते रहें। | GD6: 1. कक्षा में विद्यार्थियों को प्रेरित करने और एक सुरक्षित व सकारात्मक कक्षा संस्कृति को बढ़ावा देने के लिए उत्साहवर्धक एवं सकारात्मक भाषा का उपयोग करें। जैसे : विद्यार्थी के प्रयास की सराहना करना या सकारात्मक व्यवहार प्रदर्शित करने पर ताली बजाना आदि। 2. विद्यार्थियों के आत्मविश्वास और समझ/सीख को बढ़ाने के लिए उनसे प्रतिक्रिया लेने से पहले प्रश्न को समझने और जवाब सोचने के लिए स्पष्ट रूप से कह कर पर्याप्त समय देने पर विचार करें। 3. सभी विद्यार्थियों की सक्रिय भागीदारी सुनिश्चित करने और उन्हें व्यक्तिगत रूप से समझने के लिए प्रत्येक विद्यार्थी को प्रतिक्रिया देने के अवसर प्रदान करें साथ ही छात्रों को इसके लिए प्रोत्साहित करें। | GE6: हुक एक रोचक शुरुआत की गतिविधियाँ गणित के लिए कैसे बनाई जाए. | GM6: 694382093 | GN6: e99df1a0-26b3-47ab-a264-169b7e0d9ea4 | GO6: 45891.556 | GR6: submitted_via_web | GT6: vVLoBVrPnDmiCZ8fxF6Nin | GV6: uuid:e99df1a0-26b3-47ab-a264-169b7e0d9ea4 | GW6: 5
A7: 45891.785 | B7: 45891.825 | C7: 23.133959 79.966769 0.0 212 | D7: 23.133959 | E7: 79.966769 | F7: 0 | G7: 212 | H7: 45891 | I7: Pushpendra Singh | L7: No | M7: Katni | N7: Katni | O7: 23380200601 | S7: गणित | U7: पुरुष | V7: Suneet Pandey | W7: AN5525 | X7: हाँ | Y7: कक्षा 6 | Z7: 1 | AA7: 0 | AB7: 0 | AC7: 216 | AD7: 12 | AE7: 216 | AF7: Teaching | AG7: गणित विज्ञान | AH7: 0 | AI7: 0 | AJ7: 0 | AK7: 0 | AL7: 0 | AM7: 1 | AN7: 1 | AO7: 0 | AP7: 0 | AR7: गणित | AS7: 46 | AT7: 30 | AU7: iii.शिक्षक कक्षा की शरुआत रोचक तरीके से हुक तकनीक के उपयोग से करते है (हुक: एक तकनीक जो विद्यार्थियों को आकर्षित करने के लिए पाठ का परिचय कहानी, वस्तुओं, तथ्य और प्रश्नों के माध्यम से किया जाता है। यह 30 सेकण्ड से 3 मिनट का एक छोटा भाग होता है।) | AV7: i. व्याख्यान करते हैं। | AW7: 1 | AX7: 0 | AY7: 0 | AZ7: 0 | BA7: 0 | BC7: i.10 % से कम विद्यार्थियों की सहभागिता है और अधिकांशतः शिक्षक ही बोल रहे हैं। | BD7: i.हुक का प्रयोग | BE7: 1 | BF7: 0 | BG7: 0 | BH7: 0 | BI7: 0 | BJ7: 0 | BK7: iii.शिक्षक बंद और खुले-छोर (close & open-ended questions) वाले प्रश्नों को मिश्रित रूप से पूछते हैं | BL7: i.कोई समय नहीं दिया गया, मुख्यतः तत्काल प्रतिक्रिया मांगी गई। | BM7: i.शिक्षक अधिकांशत: प्रश्नों पर विद्यार्थियों से सामूहिक प्रतिक्रियाएँ लेते हैं। | BN7: i. अधिकांशतः हाँ/ना में सामूहिक उत्तर लेना | BO7: i.शिक्षक स्वतंत्र कार्य के लिए विद्यार्थियों को समय नहीं देते हैं। | BP7: i.शिक्षक विद्यार्थियों को समूह कार्य के अवसर प्रदान नहीं करते हैं। | BQ7: i.हाँ (यदि हाँ, तो कृपया यहाँ उदाहरण का विवरण दें) | BR7: एक बच्चे को चिलाकर बोला "कौन बोला रे" तो एक बच्ची ने बोला शुभम, shubham ने reply किया नही मैंने नही बोला उस बच्ची ने कहा एक छापड मरूंगी तो सही हो जायेगा. teacher शुभंम को वापस से डाटा | BS7: i.हाँ | BT7: i.कक्षा के नियम या दिनचर्या/रूटीन निर्धारित नहीं हैं। | BU7: iii.नहीं देखा गया (शिक्षक ने न तो रूढ़िवादिता या भेदभाव को बढ़ावा दिया/अभ्यास किया और न ही विद्यार्थियों को रूढ़िवादिता या भेदभाव के बारे में जागरूक किया) | BV7: iii.हां, रूढ़िवादिता या भेदभाव की एक या अधिक घटनाएं देखी गईं और शिक्षक ने इसे हल करने के लिए मुद्दे को स्पष्ट रूप से संबोधित किया। | BW7: ii.नहीं | CF7: iii.समझ की जाँच (CFU) प्रश्न | CG7: 0 | CH7: 0 | CI7: 1 | CJ7: 0 | CK7: 0 | CL7: 2. अनियमितता के साथ कभी कभी जाँची जाती है। | CM7: 2.कुछ त्रुटियों की पहचान की जाती है, लेकिन सुधार के सुझाव नहीं दिये जाते हैं। | CN7: 2.“अच्छा” या “ठीक है” जैसी सामान्य टिप्पणियाँ लिखी गईं। | CO7: 1.नोटबुक को साफ़ सुथरा रखने और प्रस्तुतिकरण पर कोई टिप्पणी या फीडबैक नहीं। | CP7: i.अवलोकन के दौरान विषय-विशिष्ट नोटबुक नहीं पायी गईं। | CQ7: 5 | CR7: ii.नहीं | CV7: ii.कोई दो विद्यार्थी धाराप्रवाह के साथ पढ़ पा रहें हैं। | CW7: iv. कोई भी विद्यार्थी पढ़े हुए पैराग्राफ का कम से कम 70% नही समझ पा रहा है। | CX7: iv.कोई विद्यार्थी नहीं लिख पाया या लेखन में त्रुटि है। | GC7: आपने प्रश्न के अलग-अलग प्रकारों का संतुलित उपयोग करने का उत्कृष्ट प्रयास किया; कक्षा में पढ़ाते समय इसी तरह विद्यार्थियों द्वारा विचारों की अभिव्यक्ति एवं सक्रिय भागीदारी को बढ़ाते रहें। | GD7: 1 : विद्यार्थियों के आत्मविश्वास और समझ/सीख को बढ़ाने के लिए उनसे प्रतिक्रिया लेने से पहले प्रश्न को समझने और जवाब सोचने के लिए स्पष्ट रूप से कह कर पर्याप्त समय देने पर विचार करें। 2. सभी विद्यार्थियों की सक्रिय भागीदारी सुनिश्चित करने और उन्हें व्यक्तिगत रूप से समझने के लिए प्रत्येक विद्यार्थी को प्रतिक्रिया देने के अवसर प्रदान करें साथ ही छात्रों को इसके लिए प्रोत्साहित करें।( cold calling). 3. व्यवस्थित तरीके से पढ़ाने के लिए पाठ योजना का उपयोग करने पर विचार करें और पाठ के दौरान सभी प्रमुख शिक्षण बिंदु और गतिविधियाँ प्रभावी रूप से शामिल करना सुनिश्चित करें। | GE7: Print rich बनाने एवं lession plan सैंपल के रूप में साझा करें | GM7: 694411280 | GN7: d23c8d05-265b-42ea-b08f-dcba04a0e761 | GO7: 45891.595 | GR7: submitted_via_web | GT7: vVLoBVrPnDmiCZ8fxF6Nin | GV7: uuid:d23c8d05-265b-42ea-b08f-dcba04a0e761 | GW7: 6
A8: 45891.825 | B8: 45891.837 | C8: 19.076029 72.865921 0.0 92 | D8: 19.076029 | E8: 72.865921 | F8: 0 | G8: 92 | H8: 45891 | I8: Pushpendra Singh | L8: No | M8: Katni | N8: Katni | O8: 23380200601 | S8: हिन्दी | U8: महिला | V8: indu Tiwari | W8: AN5785 | X8: प्रशिक्षण में भाग नहीं लिया | Y8: कक्षा 6 | Z8: 1 | AA8: 0 | AB8: 0 | AC8: 324 | AD8: 156 | AE8: 324 | AF8: Teaching | AG8: हिन्दी सामाजिक विज्ञान | AH8: 1 | AI8: 0 | AJ8: 0 | AK8: 0 | AL8: 0 | AM8: 0 | AN8: 0 | AO8: 1 | AP8: 0 | AR8: सामाजिक विज्ञान | AS8: 46 | AT8: 30 | AU8: i.शिक्षक कक्षा की शुरुआत, बिना किसी भूमिका के सीधे पढ़ाने से शुरू कर देते हैं। | AV8: i. व्याख्यान करते हैं। ii. विद्यार्थियों से पाठ के कुछ हिस्सों को पढ़ने के लिए कहते हैं। | AW8: 1 | AX8: 1 | AY8: 0 | AZ8: 0 | BA8: 0 | BC8: i.10 % से कम विद्यार्थियों की सहभागिता है और अधिकांशतः शिक्षक ही बोल रहे हैं। | BD8: vi.इनमें से कोई नहीं देखा गया | BE8: 0 | BF8: 0 | BG8: 0 | BH8: 0 | BI8: 0 | BJ8: 1 | BK8: ii.शिक्षक केवल बंद-छोर वाले प्रश्न (close ended) पूछते हैं | BL8: i.कोई समय नहीं दिया गया, मुख्यतः तत्काल प्रतिक्रिया मांगी गई। | BM8: i.शिक्षक अधिकांशत: प्रश्नों पर विद्यार्थियों से सामूहिक प्रतिक्रियाएँ लेते हैं। | BN8: i. अधिकांशतः हाँ/ना में सामूहिक उत्तर लेना | BO8: i.शिक्षक स्वतंत्र कार्य के लिए विद्यार्थियों को समय नहीं देते हैं। | BP8: i.शिक्षक विद्यार्थियों को समूह कार्य के अवसर प्रदान नहीं करते हैं। | BQ8: ii.नहीं | BS8: ii.नहीं | BT8: i.कक्षा के नियम या दिनचर्या/रूटीन निर्धारित नहीं हैं। | BU8: iii.नहीं देखा गया (शिक्षक ने न तो रूढ़िवादिता या भेदभाव को बढ़ावा दिया/अभ्यास किया और न ही विद्यार्थियों को रूढ़िवादिता या भेदभाव के बारे में जागरूक किया) | BV8: i.अवलोकन के दौरान रूढ़िवादिता या भेदभाव की कोई घटना नहीं देखी गई। | BW8: ii.नहीं | CF8: v.उपरोक्त में से कोई भी नहीं | CG8: 0 | CH8: 0 | CI8: 0 | CJ8: 0 | CK8: 1 | CL8: 2. अनियमितता के साथ कभी कभी जाँची जाती है। | CM8: 2.कुछ त्रुटियों की पहचान की जाती है, लेकिन सुधार के सुझाव नहीं दिये जाते हैं। | CN8: 2.“अच्छा” या “ठीक है” जैसी सामान्य टिप्पणियाँ लिखी गईं। | CO8: 1.नोटबुक को साफ़ सुथरा रखने और प्रस्तुतिकरण पर कोई टिप्पणी या फीडबैक नहीं। | CP8: i.अवलोकन के दौरान विषय-विशिष्ट नोटबुक नहीं पायी गईं। | CQ8: 5 | CR8: ii.नहीं | CV8: ii.कोई दो विद्यार्थी धाराप्रवाह के साथ पढ़ पा रहें हैं। | CW8: iv. कोई भी विद्यार्थी पढ़े हुए पैराग्राफ का कम से कम 70% नही समझ पा रहा है। | CX8: iv.कोई विद्यार्थी नहीं लिख पाया या लेखन में त्रुटि है। | GC8: शिक्षण के दो तरीकों का प्रयोग करना. बच्चो से प्रश्न पूछना | GD8: विद्यार्थियों के आत्मविश्वास और समझ/सीख को बढ़ाने के लिए उनसे प्रतिक्रिया लेने से पहले प्रश्न को समझने और जवाब सोचने के लिए स्पष्ट रूप से कह कर पर्याप्त समय देने पर विचार करें। 2. सभी विद्यार्थियों की सक्रिय भागीदारी सुनिश्चित करने और उन्हें व्यक्तिगत रूप से समझने के लिए प्रत्येक विद्यार्थी को प्रतिक्रिया देने के अवसर प्रदान करें साथ ही छात्रों को इसके लिए प्रोत्साहित करें।( कोल्ड कालिंग). 3. आपने बंद-छोर वाले प्रश्नों का उपयोग करने का अच्छा प्रयास किया; इसको आगे बढ़ाते हुए आलोचनात्मक सोच और कक्षा में अधिक जुड़ाव को प्रोत्साहित करने के लिए खुले-छोर वाले प्रश्नों को शामिल करने का प्रयास करें। | GE8: रोचक शुरुआत के लिए हुक की क्या गतिविधियाँ हो सकती है वो साझा किया जाय | GM8: 694420882 | GN8: 1aa5c983-e65e-40bb-a23c-fc14e90ae780 | GO8: 45891.607 | GR8: submitted_via_web | GT8: vVLoBVrPnDmiCZ8fxF6Nin | GV8: uuid:1aa5c983-e65e-40bb-a23c-fc14e90ae780 | GW8: 7
A9: 45891.837 | B9: 45891.849 | C9: 23.133955 79.966752 0.0 10 | D9: 23.133955 | E9: 79.966752 | F9: 0 | G9: 10 | H9: 45891 | I9: Pushpendra Singh | L9: No | M9: Mandla | N9: Beejadandi | O9: 23421402702 | S9: गणित | U9: पुरुष | V9: Chandra Mohan Patel | W9: CC6032 | X9: नहीं | Y9: कक्षा 6 | Z9: 1 | AA9: 0 | AB9: 0 | AC9: 36 | AD9: 36 | AE9: 36 | AF9: Teaching | AG9: इंग्लिश गणित | AH9: 0 | AI9: 1 | AJ9: 0 | AK9: 0 | AL9: 0 | AM9: 1 | AN9: 0 | AO9: 0 | AP9: 0 | AR9: गणित | AS9: 16 | AT9: 14 | AU9: i.शिक्षक कक्षा की शुरुआत, बिना किसी भूमिका के सीधे पढ़ाने से शुरू कर देते हैं। | AV9: i. व्याख्यान करते हैं। | AW9: 1 | AX9: 0 | AY9: 0 | AZ9: 0 | BA9: 0 | BC9: ii.10% - 40% विद्यार्थियों की सहभागिता है और शिक्षक ही अधिकांशतः बोल रहे हैं। | BD9: vi.इनमें से कोई नहीं देखा गया | BE9: 0 | BF9: 0 | BG9: 0 | BH9: 0 | BI9: 0 | BJ9: 1 | BK9: iii.शिक्षक बंद और खुले-छोर (close & open-ended questions) वाले प्रश्नों को मिश्रित रूप से पूछते हैं | BL9: i.कोई समय नहीं दिया गया, मुख्यतः तत्काल प्रतिक्रिया मांगी गई। | BM9: i.शिक्षक अधिकांशत: प्रश्नों पर विद्यार्थियों से सामूहिक प्रतिक्रियाएँ लेते हैं। | BN9: i. अधिकांशतः हाँ/ना में सामूहिक उत्तर लेना | BO9: i.शिक्षक स्वतंत्र कार्य के लिए विद्यार्थियों को समय नहीं देते हैं। | BP9: i.शिक्षक विद्यार्थियों को समूह कार्य के अवसर प्रदान नहीं करते हैं। | BQ9: ii.नहीं | BS9: i.हाँ | BT9: i.कक्षा के नियम या दिनचर्या/रूटीन निर्धारित नहीं हैं। | BU9: iii.नहीं देखा गया (शिक्षक ने न तो रूढ़िवादिता या भेदभाव को बढ़ावा दिया/अभ्यास किया और न ही विद्यार्थियों को रूढ़िवादिता या भेदभाव के बारे में जागरूक किया) | BV9: i.अवलोकन के दौरान रूढ़िवादिता या भेदभाव की कोई घटना नहीं देखी गई। | BW9: ii.नहीं | CF9: v.उपरोक्त में से कोई भी नहीं | CG9: 0 | CH9: 0 | CI9: 0 | CJ9: 0 | CK9: 1 | CL9: 1. नियमित रूप से बिना देरी के तुरंत जाँची जाती है। | CM9: 1.त्रुटियों की न तो पहचान की जाती है और न ही उन्हें सुधारा जाता है। | CN9: 1.कोई फीडबैक नहीं दिया गया। | CO9: 1.नोटबुक को साफ़ सुथरा रखने और प्रस्तुतिकरण पर कोई टिप्पणी या फीडबैक नहीं। | CP9: i.अवलोकन के दौरान विषय-विशिष्ट नोटबुक नहीं पायी गईं। | CQ9: 14 | CR9: i.हाँ | CS9: i.अधिकतर नए | CT9: i.अधिकतर विद्यार्थियों द्वारा बनाए गए | CU9: ii.कक्षा में मौजूद चार्ट/पोस्टर शैक्षणिक विषयों पर हैं, लेकिन कक्षा में शामिल/पढ़ाए नहीं जा रहे हैं। | CV9: ii.कोई दो विद्यार्थी धाराप्रवाह के साथ पढ़ पा रहें हैं। | CW9: iii.कोई एक विद्यार्थी पढ़े हुए पैराग्राफ का कम से कम 70% समझ पा रहा है। | CX9: iii.किसी एक विद्यार्थी ने बिना किसी त्रुटि के लिखा है। | GC9: 1 : कक्षा में सकारात्मक और प्रेरणादायी भाषा के उपयोग का आप बहुत अच्छा प्रयास कर रहे हैं; यह कक्षा का वातावरण उत्साहजनक और सहयोगी बनाने मे मदद करता है। 2. एक व्यवस्थित और सीखने के लिए अनुकूल कक्षा वातावरण के लिए कक्षा के नियम और दिनचर्या/रूटीन तय करना बहुत महत्वपूर्ण हैं। व्यवस्थित कक्षा एवं बेहतर परिणामों के लिए शुरू से ही विद्यार्थियों के साथ अपेक्षाएँ तय करने और उन्हें लगातार लागू करने पर विचार करें। 3. बिना किसी देरी के नियमित रूप से जाँची जाती है: यह बहुत अच्छा काम किया गया है कि विद्यार्थियों की नोटबुक को तुरंत सुधारा जाता है; इससे उनके सीखने मे सहायता करने के लिए तुरंत सुधारात्मक प्रतिक्रिया देने में मदद मिलती है। | GD9: 1 : विद्यार्थियों के आत्मविश्वास और समझ/सीख को बढ़ाने के लिए उनसे प्रतिक्रिया लेने से पहले प्रश्न को समझने और जवाब सोचने के लिए स्पष्ट रूप से कह कर पर्याप्त समय देने पर विचार करें। 2. सभी विद्यार्थियों की सक्रिय भागीदारी सुनिश्चित करने और उन्हें व्यक्तिगत रूप से समझने के लिए प्रत्येक विद्यार्थी को प्रतिक्रिया देने के अवसर प्रदान करें साथ ही छात्रों को इसके लिए प्रोत्साहित करें। 3.व्यवस्थित तरीके से पढ़ाने के लिए पाठ योजना का उपयोग करने पर विचार करें और पाठ के दौरान सभी प्रमुख शिक्षण बिंदु और गतिविधियाँ प्रभावी रूप से शामिल करना सुनिश्चित करें। | GE9: lession plan sample roop se sajha karen | GM9: 694431381 | GN9: c4d45613-8397-402a-8319-04946be730f1 | GO9: 45891.62 | GR9: submitted_via_web | GT9: vVLoBVrPnDmiCZ8fxF6Nin | GV9: uuid:c4d45613-8397-402a-8319-04946be730f1 | GW9: 8
A10: 45891.391 | B10: 45892.528 | H10: 45891 | I10: Amit Pradhan | L10: No | M10: Mandla | N10: Narayanganj | O10: 23420111302 | S10: विज्ञान | U10: महिला | V10: Neelu Kushram | W10: AQ3304 | X10: हाँ | Y10: कक्षा 6 | Z10: 1 | AA10: 0 | AB10: 0 | AC10: 216 | AD10: 24 | AE10: 24 | AF10: Teaching | AG10: अन्य | AH10: 0 | AI10: 0 | AJ10: 0 | AK10: 0 | AL10: 0 | AM10: 0 | AN10: 0 | AO10: 0 | AP10: 1 | AQ10: D. Ed. - No specification | AR10: विज्ञान | AS10: 40 | AT10: 30 | AU10: iii.शिक्षक कक्षा की शरुआत रोचक तरीके से हुक तकनीक के उपयोग से करते है (हुक: एक तकनीक जो विद्यार्थियों को आकर्षित करने के लिए पाठ का परिचय कहानी, वस्तुओं, तथ्य और प्रश्नों के माध्यम से किया जाता है। यह 30 सेकण्ड से 3 मिनट का एक छोटा भाग होता है।) | AV10: i. व्याख्यान करते हैं। | AW10: 1 | AX10: 0 | AY10: 0 | AZ10: 0 | BA10: 0 | BC10: iii.40% या उससे अधिक (अपेक्षा अनुरूप) विद्यार्थियों की सहभागिता है। | BD10: i.हुक का प्रयोग v.विद्यार्थी के कार्यों (अकादमिक/गैर अकादमिक) पर रचनात्मक फीडबैक (Constructive Feedback) | BE10: 1 | BF10: 0 | BG10: 0 | BH10: 0 | BI10: 1 | BJ10: 0 | BK10: iii.शिक्षक बंद और खुले-छोर (close & open-ended questions) वाले प्रश्नों को मिश्रित रूप से पूछते हैं | BL10: i.कोई समय नहीं दिया गया, मुख्यतः तत्काल प्रतिक्रिया मांगी गई। | BM10: i.शिक्षक अधिकांशत: प्रश्नों पर विद्यार्थियों से सामूहिक प्रतिक्रियाएँ लेते हैं। | BN10: ii.हाँ, अधिकांशतः कुछ बुनियादी समझ की जाँच की तकनीक (हाथ उठाना, अंगूठा दिखाना, आदि) का प्रयोग किया गया | BO10: iv.शिक्षक स्वतंत्र कार्य के लिए विद्यार्थियों को समय देते हैं और विद्यार्थियों के कार्य की जाँच करने और उनकी सहायता करने के लिए कक्षा में भ्रमण भी करते हैं। | BP10: i.शिक्षक विद्यार्थियों को समूह कार्य के अवसर प्रदान नहीं करते हैं। | BQ10: ii.नहीं | BS10: ii.नहीं | BT10: ii.कक्षा के नियम या दिनचर्या/ रूटीन निर्धारित हैं, लेकिन नियमित रूप से सुदृढ़ नहीं किए जाते हैं (आवश्यकता होने पर भी)। | BU10: iii.नहीं देखा गया (शिक्षक ने न तो रूढ़िवादिता या भेदभाव को बढ़ावा दिया/अभ्यास किया और न ही विद्यार्थियों को रूढ़िवादिता या भेदभाव के बारे में जागरूक किया) | BV10: i.अवलोकन के दौरान रूढ़िवादिता या भेदभाव की कोई घटना नहीं देखी गई। | BW10: ii.नहीं | CF10: ii.विषय से संबंधित गतिविधियाँ iii.समझ की जाँच (CFU) प्रश्न | CG10: 0 | CH10: 1 | CI10: 1 | CJ10: 0 | CK10: 0 | CL10: 2. अनियमितता के साथ कभी कभी जाँची जाती है। | CM10: 1.त्रुटियों की न तो पहचान की जाती है और न ही उन्हें सुधारा जाता है। | CN10: 2.“अच्छा” या “ठीक है” जैसी सामान्य टिप्पणियाँ लिखी गईं। | CO10: 1.नोटबुक को साफ़ सुथरा रखने और प्रस्तुतिकरण पर कोई टिप्पणी या फीडबैक नहीं। | CP10: ii.50% से कम विद्यार्थी विषय-विशिष्ट नोटबुक में काम करते हैं। | CQ10: 20 | CR10: i.हाँ | CS10: ii.अधिकतर पुराने (फटे या ऐसे जिनमें जानकारी स्पष्ट दिख नहीं रही) | CT10: i.अधिकतर विद्यार्थियों द्वारा बनाए गए | CU10: ii.कक्षा में मौजूद चार्ट/पोस्टर शैक्षणिक विषयों पर हैं, लेकिन कक्षा में शामिल/पढ़ाए नहीं जा रहे हैं। | CV10: ii.कोई दो विद्यार्थी धाराप्रवाह के साथ पढ़ पा रहें हैं। | CW10: iii.कोई एक विद्यार्थी पढ़े हुए पैराग्राफ का कम से कम 70% समझ पा रहा है। | CX10: ii.किन्ही दो विद्यार्थियों ने बिना किसी त्रुटि के लिखा है। | GC10: 1. Ma'am was circulating continously and correcting students individually 2. She encouraged on of the students , Aanaya , to help her friend Janvi. 3. Most of her teaching was question led, instead of just telling them things | GD10: 1. All the charts in the classroom were old and made by students of the previous year - suggested that she involve the students in making charts and renew them regularly. We also made a "Why does this happen?" chart after the observation. 2. Suggested using cold calling - as she was at times struggling with number of studnets who had their hands raised. | GE10: - | GF10: - | GM10: 694657344 | GN10: 52523dc6-5cf6-474b-a7a5-e7242f7d4953 | GO10: 45892.299 | GR10: submitted_via_web | GT10: vVLoBVrPnDmiCZ8fxF6Nin | GV10: uuid:52523dc6-5cf6-474b-a7a5-e7242f7d4953 | GW10: 9
